2022-05-24 12:26:18,639 INFO: errors [in D:\My-Projects\U\projects\Fyyur\main.py:495]
2022-05-24 12:26:37,676 ERROR: Exception on /venues/create [GET] [in D:\My-Projects\U\projects\TodoApp\venv\lib\site-packages\flask\app.py:1455]
Traceback (most recent call last):
  File "D:\My-Projects\U\projects\TodoApp\venv\lib\site-packages\flask\app.py", line 2077, in wsgi_app
    response = self.full_dispatch_request()
  File "D:\My-Projects\U\projects\TodoApp\venv\lib\site-packages\flask\app.py", line 1525, in full_dispatch_request
    rv = self.handle_user_exception(e)
  File "D:\My-Projects\U\projects\TodoApp\venv\lib\site-packages\flask\app.py", line 1523, in full_dispatch_request
    rv = self.dispatch_request()
  File "D:\My-Projects\U\projects\TodoApp\venv\lib\site-packages\flask\app.py", line 1509, in dispatch_request
    return self.ensure_sync(self.view_functions[rule.endpoint])(**req.view_args)
  File "D:\My-Projects\U\projects\Fyyur\main.py", line 206, in create_venue_form
    form = VenueForm()
NameError: name 'VenueForm' is not defined
2022-05-24 12:26:42,187 ERROR: Exception on /artists/create [GET] [in D:\My-Projects\U\projects\TodoApp\venv\lib\site-packages\flask\app.py:1455]
Traceback (most recent call last):
  File "D:\My-Projects\U\projects\TodoApp\venv\lib\site-packages\flask\app.py", line 2077, in wsgi_app
    response = self.full_dispatch_request()
  File "D:\My-Projects\U\projects\TodoApp\venv\lib\site-packages\flask\app.py", line 1525, in full_dispatch_request
    rv = self.handle_user_exception(e)
  File "D:\My-Projects\U\projects\TodoApp\venv\lib\site-packages\flask\app.py", line 1523, in full_dispatch_request
    rv = self.dispatch_request()
  File "D:\My-Projects\U\projects\TodoApp\venv\lib\site-packages\flask\app.py", line 1509, in dispatch_request
    return self.ensure_sync(self.view_functions[rule.endpoint])(**req.view_args)
  File "D:\My-Projects\U\projects\Fyyur\main.py", line 399, in create_artist_form
    form = ArtistForm()
NameError: name 'ArtistForm' is not defined
2022-05-24 12:26:49,507 ERROR: Exception on /shows/create [GET] [in D:\My-Projects\U\projects\TodoApp\venv\lib\site-packages\flask\app.py:1455]
Traceback (most recent call last):
  File "D:\My-Projects\U\projects\TodoApp\venv\lib\site-packages\flask\app.py", line 2077, in wsgi_app
    response = self.full_dispatch_request()
  File "D:\My-Projects\U\projects\TodoApp\venv\lib\site-packages\flask\app.py", line 1525, in full_dispatch_request
    rv = self.handle_user_exception(e)
  File "D:\My-Projects\U\projects\TodoApp\venv\lib\site-packages\flask\app.py", line 1523, in full_dispatch_request
    rv = self.dispatch_request()
  File "D:\My-Projects\U\projects\TodoApp\venv\lib\site-packages\flask\app.py", line 1509, in dispatch_request
    return self.ensure_sync(self.view_functions[rule.endpoint])(**req.view_args)
  File "D:\My-Projects\U\projects\Fyyur\main.py", line 463, in create_shows
    form = ShowForm()
NameError: name 'ShowForm' is not defined
2022-05-25 18:34:10,711 INFO: errors [in D:\My-Projects\U\projects\Fyyur\main.py:495]
2022-05-25 18:39:00,341 ERROR: Exception on /venues/create [GET] [in D:\My-Projects\U\projects\TodoApp\venv\lib\site-packages\flask\app.py:1455]
Traceback (most recent call last):
  File "D:\My-Projects\U\projects\TodoApp\venv\lib\site-packages\flask\app.py", line 2077, in wsgi_app
    response = self.full_dispatch_request()
  File "D:\My-Projects\U\projects\TodoApp\venv\lib\site-packages\flask\app.py", line 1525, in full_dispatch_request
    rv = self.handle_user_exception(e)
  File "D:\My-Projects\U\projects\TodoApp\venv\lib\site-packages\flask\app.py", line 1523, in full_dispatch_request
    rv = self.dispatch_request()
  File "D:\My-Projects\U\projects\TodoApp\venv\lib\site-packages\flask\app.py", line 1509, in dispatch_request
    return self.ensure_sync(self.view_functions[rule.endpoint])(**req.view_args)
  File "D:\My-Projects\U\projects\Fyyur\main.py", line 206, in create_venue_form
    form = VenueForm()
NameError: name 'VenueForm' is not defined
2022-05-25 18:39:09,186 ERROR: Exception on /artists/create [GET] [in D:\My-Projects\U\projects\TodoApp\venv\lib\site-packages\flask\app.py:1455]
Traceback (most recent call last):
  File "D:\My-Projects\U\projects\TodoApp\venv\lib\site-packages\flask\app.py", line 2077, in wsgi_app
    response = self.full_dispatch_request()
  File "D:\My-Projects\U\projects\TodoApp\venv\lib\site-packages\flask\app.py", line 1525, in full_dispatch_request
    rv = self.handle_user_exception(e)
  File "D:\My-Projects\U\projects\TodoApp\venv\lib\site-packages\flask\app.py", line 1523, in full_dispatch_request
    rv = self.dispatch_request()
  File "D:\My-Projects\U\projects\TodoApp\venv\lib\site-packages\flask\app.py", line 1509, in dispatch_request
    return self.ensure_sync(self.view_functions[rule.endpoint])(**req.view_args)
  File "D:\My-Projects\U\projects\Fyyur\main.py", line 399, in create_artist_form
    form = ArtistForm()
NameError: name 'ArtistForm' is not defined
2022-05-25 18:39:20,971 ERROR: Exception on /shows/create [GET] [in D:\My-Projects\U\projects\TodoApp\venv\lib\site-packages\flask\app.py:1455]
Traceback (most recent call last):
  File "D:\My-Projects\U\projects\TodoApp\venv\lib\site-packages\flask\app.py", line 2077, in wsgi_app
    response = self.full_dispatch_request()
  File "D:\My-Projects\U\projects\TodoApp\venv\lib\site-packages\flask\app.py", line 1525, in full_dispatch_request
    rv = self.handle_user_exception(e)
  File "D:\My-Projects\U\projects\TodoApp\venv\lib\site-packages\flask\app.py", line 1523, in full_dispatch_request
    rv = self.dispatch_request()
  File "D:\My-Projects\U\projects\TodoApp\venv\lib\site-packages\flask\app.py", line 1509, in dispatch_request
    return self.ensure_sync(self.view_functions[rule.endpoint])(**req.view_args)
  File "D:\My-Projects\U\projects\Fyyur\main.py", line 463, in create_shows
    form = ShowForm()
NameError: name 'ShowForm' is not defined
2022-05-25 18:40:20,423 ERROR: Exception on /shows/create [GET] [in D:\My-Projects\U\projects\TodoApp\venv\lib\site-packages\flask\app.py:1455]
Traceback (most recent call last):
  File "D:\My-Projects\U\projects\TodoApp\venv\lib\site-packages\flask\app.py", line 2077, in wsgi_app
    response = self.full_dispatch_request()
  File "D:\My-Projects\U\projects\TodoApp\venv\lib\site-packages\flask\app.py", line 1525, in full_dispatch_request
    rv = self.handle_user_exception(e)
  File "D:\My-Projects\U\projects\TodoApp\venv\lib\site-packages\flask\app.py", line 1523, in full_dispatch_request
    rv = self.dispatch_request()
  File "D:\My-Projects\U\projects\TodoApp\venv\lib\site-packages\flask\app.py", line 1509, in dispatch_request
    return self.ensure_sync(self.view_functions[rule.endpoint])(**req.view_args)
  File "D:\My-Projects\U\projects\Fyyur\main.py", line 463, in create_shows
    form = ShowForm()
NameError: name 'ShowForm' is not defined
2022-05-25 18:40:20,521 ERROR: Exception on /shows/create [GET] [in D:\My-Projects\U\projects\TodoApp\venv\lib\site-packages\flask\app.py:1455]
Traceback (most recent call last):
  File "D:\My-Projects\U\projects\TodoApp\venv\lib\site-packages\flask\app.py", line 2077, in wsgi_app
    response = self.full_dispatch_request()
  File "D:\My-Projects\U\projects\TodoApp\venv\lib\site-packages\flask\app.py", line 1525, in full_dispatch_request
    rv = self.handle_user_exception(e)
  File "D:\My-Projects\U\projects\TodoApp\venv\lib\site-packages\flask\app.py", line 1523, in full_dispatch_request
    rv = self.dispatch_request()
  File "D:\My-Projects\U\projects\TodoApp\venv\lib\site-packages\flask\app.py", line 1509, in dispatch_request
    return self.ensure_sync(self.view_functions[rule.endpoint])(**req.view_args)
  File "D:\My-Projects\U\projects\Fyyur\main.py", line 463, in create_shows
    form = ShowForm()
NameError: name 'ShowForm' is not defined
2022-05-25 19:02:34,964 INFO: errors [in D:\My-Projects\U\projects\Fyyur\main.py:495]
2022-05-26 09:27:51,232 INFO: errors [in D:\My-Projects\U\projects\Fyyur\main.py:507]
2022-05-26 09:30:24,107 ERROR: Exception on /venues/create [POST] [in D:\My-Projects\U\projects\TodoApp\venv\lib\site-packages\flask\app.py:1455]
Traceback (most recent call last):
  File "D:\My-Projects\U\projects\TodoApp\venv\lib\site-packages\sqlalchemy\engine\base.py", line 1819, in _execute_context
    self.dialect.do_execute(
  File "D:\My-Projects\U\projects\TodoApp\venv\lib\site-packages\sqlalchemy\engine\default.py", line 732, in do_execute
    cursor.execute(statement, parameters)
psycopg2.errors.UndefinedTable: relation "Venue" does not exist
LINE 1: INSERT INTO "Venue" (name, city, state, address, phone, imag...
                    ^


The above exception was the direct cause of the following exception:

Traceback (most recent call last):
  File "D:\My-Projects\U\projects\TodoApp\venv\lib\site-packages\flask\app.py", line 2077, in wsgi_app
    response = self.full_dispatch_request()
  File "D:\My-Projects\U\projects\TodoApp\venv\lib\site-packages\flask\app.py", line 1525, in full_dispatch_request
    rv = self.handle_user_exception(e)
  File "D:\My-Projects\U\projects\TodoApp\venv\lib\site-packages\flask\app.py", line 1523, in full_dispatch_request
    rv = self.dispatch_request()
  File "D:\My-Projects\U\projects\TodoApp\venv\lib\site-packages\flask\app.py", line 1509, in dispatch_request
    return self.ensure_sync(self.view_functions[rule.endpoint])(**req.view_args)
  File "D:\My-Projects\U\projects\Fyyur\main.py", line 222, in create_venue_submission
    db.session.commit()
  File "<string>", line 2, in commit
  File "D:\My-Projects\U\projects\TodoApp\venv\lib\site-packages\sqlalchemy\orm\session.py", line 1435, in commit
    self._transaction.commit(_to_root=self.future)
  File "D:\My-Projects\U\projects\TodoApp\venv\lib\site-packages\sqlalchemy\orm\session.py", line 829, in commit
    self._prepare_impl()
  File "D:\My-Projects\U\projects\TodoApp\venv\lib\site-packages\sqlalchemy\orm\session.py", line 808, in _prepare_impl
    self.session.flush()
  File "D:\My-Projects\U\projects\TodoApp\venv\lib\site-packages\sqlalchemy\orm\session.py", line 3367, in flush
    self._flush(objects)
  File "D:\My-Projects\U\projects\TodoApp\venv\lib\site-packages\sqlalchemy\orm\session.py", line 3507, in _flush
    transaction.rollback(_capture_exception=True)
  File "D:\My-Projects\U\projects\TodoApp\venv\lib\site-packages\sqlalchemy\util\langhelpers.py", line 70, in __exit__
    compat.raise_(
  File "D:\My-Projects\U\projects\TodoApp\venv\lib\site-packages\sqlalchemy\util\compat.py", line 207, in raise_
    raise exception
  File "D:\My-Projects\U\projects\TodoApp\venv\lib\site-packages\sqlalchemy\orm\session.py", line 3467, in _flush
    flush_context.execute()
  File "D:\My-Projects\U\projects\TodoApp\venv\lib\site-packages\sqlalchemy\orm\unitofwork.py", line 456, in execute
    rec.execute(self)
  File "D:\My-Projects\U\projects\TodoApp\venv\lib\site-packages\sqlalchemy\orm\unitofwork.py", line 630, in execute
    util.preloaded.orm_persistence.save_obj(
  File "D:\My-Projects\U\projects\TodoApp\venv\lib\site-packages\sqlalchemy\orm\persistence.py", line 245, in save_obj
    _emit_insert_statements(
  File "D:\My-Projects\U\projects\TodoApp\venv\lib\site-packages\sqlalchemy\orm\persistence.py", line 1238, in _emit_insert_statements
    result = connection._execute_20(
  File "D:\My-Projects\U\projects\TodoApp\venv\lib\site-packages\sqlalchemy\engine\base.py", line 1631, in _execute_20
    return meth(self, args_10style, kwargs_10style, execution_options)
  File "D:\My-Projects\U\projects\TodoApp\venv\lib\site-packages\sqlalchemy\sql\elements.py", line 325, in _execute_on_connection
    return connection._execute_clauseelement(
  File "D:\My-Projects\U\projects\TodoApp\venv\lib\site-packages\sqlalchemy\engine\base.py", line 1498, in _execute_clauseelement
    ret = self._execute_context(
  File "D:\My-Projects\U\projects\TodoApp\venv\lib\site-packages\sqlalchemy\engine\base.py", line 1862, in _execute_context
    self._handle_dbapi_exception(
  File "D:\My-Projects\U\projects\TodoApp\venv\lib\site-packages\sqlalchemy\engine\base.py", line 2043, in _handle_dbapi_exception
    util.raise_(
  File "D:\My-Projects\U\projects\TodoApp\venv\lib\site-packages\sqlalchemy\util\compat.py", line 207, in raise_
    raise exception
  File "D:\My-Projects\U\projects\TodoApp\venv\lib\site-packages\sqlalchemy\engine\base.py", line 1819, in _execute_context
    self.dialect.do_execute(
  File "D:\My-Projects\U\projects\TodoApp\venv\lib\site-packages\sqlalchemy\engine\default.py", line 732, in do_execute
    cursor.execute(statement, parameters)
sqlalchemy.exc.ProgrammingError: (psycopg2.errors.UndefinedTable) relation "Venue" does not exist
LINE 1: INSERT INTO "Venue" (name, city, state, address, phone, imag...
                    ^

[SQL: INSERT INTO "Venue" (name, city, state, address, phone, image_link, facebook_link) VALUES (%(name)s, %(city)s, %(state)s, %(address)s, %(phone)s, %(image_link)s, %(facebook_link)s) RETURNING "Venue".id]
[parameters: {'name': 'sdsfv', 'city': 'TestCity', 'state': 'AL', 'address': 'Dodoma Mjini, Dodoma', 'phone': '232323', 'image_link': 'https://images.unsplash.com/photo-1507838153414-b4b713384a76?crop=entropy&cs=tinysrgb&fm=jpg&ixlib=rb-1.2.1&q=60&raw_url=true&ixid=MnwxMjA3fDB8MHxzZWFyY2h8Mnx8bXVzaWN8ZW58MHx8MHx8&auto=format&fit=crop&w=500', 'facebook_link': 'advzvzcv'}]
(Background on this error at: https://sqlalche.me/e/14/f405)
2022-05-26 09:32:24,695 ERROR: Exception on /venues/create [POST] [in D:\My-Projects\U\projects\TodoApp\venv\lib\site-packages\flask\app.py:1455]
Traceback (most recent call last):
  File "D:\My-Projects\U\projects\TodoApp\venv\lib\site-packages\sqlalchemy\engine\base.py", line 1819, in _execute_context
    self.dialect.do_execute(
  File "D:\My-Projects\U\projects\TodoApp\venv\lib\site-packages\sqlalchemy\engine\default.py", line 732, in do_execute
    cursor.execute(statement, parameters)
psycopg2.errors.UndefinedTable: relation "Venue" does not exist
LINE 1: INSERT INTO "Venue" (name, city, state, address, phone, imag...
                    ^


The above exception was the direct cause of the following exception:

Traceback (most recent call last):
  File "D:\My-Projects\U\projects\TodoApp\venv\lib\site-packages\flask\app.py", line 2077, in wsgi_app
    response = self.full_dispatch_request()
  File "D:\My-Projects\U\projects\TodoApp\venv\lib\site-packages\flask\app.py", line 1525, in full_dispatch_request
    rv = self.handle_user_exception(e)
  File "D:\My-Projects\U\projects\TodoApp\venv\lib\site-packages\flask\app.py", line 1523, in full_dispatch_request
    rv = self.dispatch_request()
  File "D:\My-Projects\U\projects\TodoApp\venv\lib\site-packages\flask\app.py", line 1509, in dispatch_request
    return self.ensure_sync(self.view_functions[rule.endpoint])(**req.view_args)
  File "D:\My-Projects\U\projects\Fyyur\main.py", line 222, in create_venue_submission
    db.session.commit()
  File "<string>", line 2, in commit
  File "D:\My-Projects\U\projects\TodoApp\venv\lib\site-packages\sqlalchemy\orm\session.py", line 1435, in commit
    self._transaction.commit(_to_root=self.future)
  File "D:\My-Projects\U\projects\TodoApp\venv\lib\site-packages\sqlalchemy\orm\session.py", line 829, in commit
    self._prepare_impl()
  File "D:\My-Projects\U\projects\TodoApp\venv\lib\site-packages\sqlalchemy\orm\session.py", line 808, in _prepare_impl
    self.session.flush()
  File "D:\My-Projects\U\projects\TodoApp\venv\lib\site-packages\sqlalchemy\orm\session.py", line 3367, in flush
    self._flush(objects)
  File "D:\My-Projects\U\projects\TodoApp\venv\lib\site-packages\sqlalchemy\orm\session.py", line 3507, in _flush
    transaction.rollback(_capture_exception=True)
  File "D:\My-Projects\U\projects\TodoApp\venv\lib\site-packages\sqlalchemy\util\langhelpers.py", line 70, in __exit__
    compat.raise_(
  File "D:\My-Projects\U\projects\TodoApp\venv\lib\site-packages\sqlalchemy\util\compat.py", line 207, in raise_
    raise exception
  File "D:\My-Projects\U\projects\TodoApp\venv\lib\site-packages\sqlalchemy\orm\session.py", line 3467, in _flush
    flush_context.execute()
  File "D:\My-Projects\U\projects\TodoApp\venv\lib\site-packages\sqlalchemy\orm\unitofwork.py", line 456, in execute
    rec.execute(self)
  File "D:\My-Projects\U\projects\TodoApp\venv\lib\site-packages\sqlalchemy\orm\unitofwork.py", line 630, in execute
    util.preloaded.orm_persistence.save_obj(
  File "D:\My-Projects\U\projects\TodoApp\venv\lib\site-packages\sqlalchemy\orm\persistence.py", line 245, in save_obj
    _emit_insert_statements(
  File "D:\My-Projects\U\projects\TodoApp\venv\lib\site-packages\sqlalchemy\orm\persistence.py", line 1238, in _emit_insert_statements
    result = connection._execute_20(
  File "D:\My-Projects\U\projects\TodoApp\venv\lib\site-packages\sqlalchemy\engine\base.py", line 1631, in _execute_20
    return meth(self, args_10style, kwargs_10style, execution_options)
  File "D:\My-Projects\U\projects\TodoApp\venv\lib\site-packages\sqlalchemy\sql\elements.py", line 325, in _execute_on_connection
    return connection._execute_clauseelement(
  File "D:\My-Projects\U\projects\TodoApp\venv\lib\site-packages\sqlalchemy\engine\base.py", line 1498, in _execute_clauseelement
    ret = self._execute_context(
  File "D:\My-Projects\U\projects\TodoApp\venv\lib\site-packages\sqlalchemy\engine\base.py", line 1862, in _execute_context
    self._handle_dbapi_exception(
  File "D:\My-Projects\U\projects\TodoApp\venv\lib\site-packages\sqlalchemy\engine\base.py", line 2043, in _handle_dbapi_exception
    util.raise_(
  File "D:\My-Projects\U\projects\TodoApp\venv\lib\site-packages\sqlalchemy\util\compat.py", line 207, in raise_
    raise exception
  File "D:\My-Projects\U\projects\TodoApp\venv\lib\site-packages\sqlalchemy\engine\base.py", line 1819, in _execute_context
    self.dialect.do_execute(
  File "D:\My-Projects\U\projects\TodoApp\venv\lib\site-packages\sqlalchemy\engine\default.py", line 732, in do_execute
    cursor.execute(statement, parameters)
sqlalchemy.exc.ProgrammingError: (psycopg2.errors.UndefinedTable) relation "Venue" does not exist
LINE 1: INSERT INTO "Venue" (name, city, state, address, phone, imag...
                    ^

[SQL: INSERT INTO "Venue" (name, city, state, address, phone, image_link, facebook_link) VALUES (%(name)s, %(city)s, %(state)s, %(address)s, %(phone)s, %(image_link)s, %(facebook_link)s) RETURNING "Venue".id]
[parameters: {'name': 'dfbdfb', 'city': 'TestCity', 'state': 'AL', 'address': 'test', 'phone': '7890', 'image_link': 'https://images.unsplash.com/photo-1507838153414-b4b713384a76?crop=entropy&cs=tinysrgb&fm=jpg&ixlib=rb-1.2.1&q=60&raw_url=true&ixid=MnwxMjA3fDB8MHxzZWFyY2h8Mnx8bXVzaWN8ZW58MHx8MHx8&auto=format&fit=crop&w=500', 'facebook_link': 'advzvzcv'}]
(Background on this error at: https://sqlalche.me/e/14/f405)
2022-05-26 10:08:45,129 ERROR: Exception on /venues/100 [GET] [in D:\My-Projects\U\projects\TodoApp\venv\lib\site-packages\flask\app.py:1455]
Traceback (most recent call last):
  File "D:\My-Projects\U\projects\TodoApp\venv\lib\site-packages\flask\app.py", line 2077, in wsgi_app
    response = self.full_dispatch_request()
  File "D:\My-Projects\U\projects\TodoApp\venv\lib\site-packages\flask\app.py", line 1525, in full_dispatch_request
    rv = self.handle_user_exception(e)
  File "D:\My-Projects\U\projects\TodoApp\venv\lib\site-packages\flask\app.py", line 1523, in full_dispatch_request
    rv = self.dispatch_request()
  File "D:\My-Projects\U\projects\TodoApp\venv\lib\site-packages\flask\app.py", line 1509, in dispatch_request
    return self.ensure_sync(self.view_functions[rule.endpoint])(**req.view_args)
  File "D:\My-Projects\U\projects\Fyyur\main.py", line 198, in show_venue
    data = list(filter(lambda d: d['id'] == venue_id, [data1, data2, data3]))[0]
IndexError: list index out of range
2022-05-26 10:11:20,012 ERROR: Exception on /venues/4 [GET] [in D:\My-Projects\U\projects\TodoApp\venv\lib\site-packages\flask\app.py:1455]
Traceback (most recent call last):
  File "D:\My-Projects\U\projects\TodoApp\venv\lib\site-packages\flask\app.py", line 2077, in wsgi_app
    response = self.full_dispatch_request()
  File "D:\My-Projects\U\projects\TodoApp\venv\lib\site-packages\flask\app.py", line 1525, in full_dispatch_request
    rv = self.handle_user_exception(e)
  File "D:\My-Projects\U\projects\TodoApp\venv\lib\site-packages\flask\app.py", line 1523, in full_dispatch_request
    rv = self.dispatch_request()
  File "D:\My-Projects\U\projects\TodoApp\venv\lib\site-packages\flask\app.py", line 1509, in dispatch_request
    return self.ensure_sync(self.view_functions[rule.endpoint])(**req.view_args)
  File "D:\My-Projects\U\projects\Fyyur\main.py", line 198, in show_venue
    data = list(filter(lambda d: d['id'] == venue_id, [data1, data2, data3]))[0]
IndexError: list index out of range
2022-05-26 10:14:31,774 INFO: errors [in D:\My-Projects\U\projects\Fyyur\main.py:510]
2022-05-26 10:14:55,104 ERROR: Exception on /venues/1 [GET] [in D:\My-Projects\U\projects\TodoApp\venv\lib\site-packages\flask\app.py:1455]
Traceback (most recent call last):
  File "D:\My-Projects\U\projects\TodoApp\venv\lib\site-packages\flask\app.py", line 2077, in wsgi_app
    response = self.full_dispatch_request()
  File "D:\My-Projects\U\projects\TodoApp\venv\lib\site-packages\flask\app.py", line 1525, in full_dispatch_request
    rv = self.handle_user_exception(e)
  File "D:\My-Projects\U\projects\TodoApp\venv\lib\site-packages\flask\app.py", line 1523, in full_dispatch_request
    rv = self.dispatch_request()
  File "D:\My-Projects\U\projects\TodoApp\venv\lib\site-packages\flask\app.py", line 1509, in dispatch_request
    return self.ensure_sync(self.view_functions[rule.endpoint])(**req.view_args)
  File "D:\My-Projects\U\projects\Fyyur\main.py", line 200, in show_venue
    data = list(filter(lambda d: d['id'] == venue_id, [my_data]))[0]
  File "D:\My-Projects\U\projects\Fyyur\main.py", line 200, in <lambda>
    data = list(filter(lambda d: d['id'] == venue_id, [my_data]))[0]
TypeError: list indices must be integers or slices, not str
2022-05-26 10:16:45,034 ERROR: Exception on /venues/2 [GET] [in D:\My-Projects\U\projects\TodoApp\venv\lib\site-packages\flask\app.py:1455]
Traceback (most recent call last):
  File "D:\My-Projects\U\projects\TodoApp\venv\lib\site-packages\flask\app.py", line 2077, in wsgi_app
    response = self.full_dispatch_request()
  File "D:\My-Projects\U\projects\TodoApp\venv\lib\site-packages\flask\app.py", line 1525, in full_dispatch_request
    rv = self.handle_user_exception(e)
  File "D:\My-Projects\U\projects\TodoApp\venv\lib\site-packages\flask\app.py", line 1523, in full_dispatch_request
    rv = self.dispatch_request()
  File "D:\My-Projects\U\projects\TodoApp\venv\lib\site-packages\flask\app.py", line 1509, in dispatch_request
    return self.ensure_sync(self.view_functions[rule.endpoint])(**req.view_args)
  File "D:\My-Projects\U\projects\Fyyur\main.py", line 200, in show_venue
    data = list(filter(lambda d: d['id'] == venue_id, [my_data]))[0]
  File "D:\My-Projects\U\projects\Fyyur\main.py", line 200, in <lambda>
    data = list(filter(lambda d: d['id'] == venue_id, [my_data]))[0]
TypeError: list indices must be integers or slices, not str
2022-05-26 10:16:46,471 ERROR: Exception on /venues/4 [GET] [in D:\My-Projects\U\projects\TodoApp\venv\lib\site-packages\flask\app.py:1455]
Traceback (most recent call last):
  File "D:\My-Projects\U\projects\TodoApp\venv\lib\site-packages\flask\app.py", line 2077, in wsgi_app
    response = self.full_dispatch_request()
  File "D:\My-Projects\U\projects\TodoApp\venv\lib\site-packages\flask\app.py", line 1525, in full_dispatch_request
    rv = self.handle_user_exception(e)
  File "D:\My-Projects\U\projects\TodoApp\venv\lib\site-packages\flask\app.py", line 1523, in full_dispatch_request
    rv = self.dispatch_request()
  File "D:\My-Projects\U\projects\TodoApp\venv\lib\site-packages\flask\app.py", line 1509, in dispatch_request
    return self.ensure_sync(self.view_functions[rule.endpoint])(**req.view_args)
  File "D:\My-Projects\U\projects\Fyyur\main.py", line 200, in show_venue
    data = list(filter(lambda d: d['id'] == venue_id, [my_data]))[0]
  File "D:\My-Projects\U\projects\Fyyur\main.py", line 200, in <lambda>
    data = list(filter(lambda d: d['id'] == venue_id, [my_data]))[0]
TypeError: list indices must be integers or slices, not str
2022-05-26 10:17:13,868 INFO: errors [in D:\My-Projects\U\projects\Fyyur\main.py:511]
2022-05-26 10:17:18,475 ERROR: Exception on /venues/4 [GET] [in D:\My-Projects\U\projects\TodoApp\venv\lib\site-packages\flask\app.py:1455]
Traceback (most recent call last):
  File "D:\My-Projects\U\projects\TodoApp\venv\lib\site-packages\flask\app.py", line 2077, in wsgi_app
    response = self.full_dispatch_request()
  File "D:\My-Projects\U\projects\TodoApp\venv\lib\site-packages\flask\app.py", line 1525, in full_dispatch_request
    rv = self.handle_user_exception(e)
  File "D:\My-Projects\U\projects\TodoApp\venv\lib\site-packages\flask\app.py", line 1523, in full_dispatch_request
    rv = self.dispatch_request()
  File "D:\My-Projects\U\projects\TodoApp\venv\lib\site-packages\flask\app.py", line 1509, in dispatch_request
    return self.ensure_sync(self.view_functions[rule.endpoint])(**req.view_args)
  File "D:\My-Projects\U\projects\Fyyur\main.py", line 201, in show_venue
    data = list(filter(lambda d: d['id'] == venue_id, [my_data]))[0]
  File "D:\My-Projects\U\projects\Fyyur\main.py", line 201, in <lambda>
    data = list(filter(lambda d: d['id'] == venue_id, [my_data]))[0]
TypeError: list indices must be integers or slices, not str
2022-05-26 10:18:28,425 INFO: errors [in D:\My-Projects\U\projects\Fyyur\main.py:511]
2022-05-26 10:19:33,162 INFO: errors [in D:\My-Projects\U\projects\Fyyur\main.py:513]
2022-05-26 10:19:59,482 ERROR: Exception on /venues/create [POST] [in D:\My-Projects\U\projects\TodoApp\venv\lib\site-packages\flask\app.py:1455]
Traceback (most recent call last):
  File "D:\My-Projects\U\projects\TodoApp\venv\lib\site-packages\flask\app.py", line 2077, in wsgi_app
    response = self.full_dispatch_request()
  File "D:\My-Projects\U\projects\TodoApp\venv\lib\site-packages\flask\app.py", line 1525, in full_dispatch_request
    rv = self.handle_user_exception(e)
  File "D:\My-Projects\U\projects\TodoApp\venv\lib\site-packages\flask\app.py", line 1523, in full_dispatch_request
    rv = self.dispatch_request()
  File "D:\My-Projects\U\projects\TodoApp\venv\lib\site-packages\flask\app.py", line 1509, in dispatch_request
    return self.ensure_sync(self.view_functions[rule.endpoint])(**req.view_args)
  File "D:\My-Projects\U\projects\Fyyur\main.py", line 233, in create_venue_submission
    flash('Venue ' + request.form['name'] + ' was successfully listed!')
  File "D:\My-Projects\U\projects\TodoApp\venv\lib\site-packages\flask\helpers.py", line 389, in flash
    session["_flashes"] = flashes
  File "D:\My-Projects\U\projects\TodoApp\venv\lib\site-packages\flask\sessions.py", line 97, in _fail
    raise RuntimeError(
RuntimeError: The session is unavailable because no secret key was set.  Set the secret_key on the application to something unique and secret.
2022-05-26 10:28:03,906 INFO: errors [in D:\My-Projects\U\projects\Fyyur\main.py:522]
2022-05-26 10:28:39,132 ERROR: Exception on /venues/create [POST] [in D:\My-Projects\U\projects\TodoApp\venv\lib\site-packages\flask\app.py:1455]
Traceback (most recent call last):
  File "D:\My-Projects\U\projects\TodoApp\venv\lib\site-packages\flask\app.py", line 2077, in wsgi_app
    response = self.full_dispatch_request()
  File "D:\My-Projects\U\projects\TodoApp\venv\lib\site-packages\flask\app.py", line 1525, in full_dispatch_request
    rv = self.handle_user_exception(e)
  File "D:\My-Projects\U\projects\TodoApp\venv\lib\site-packages\flask\app.py", line 1523, in full_dispatch_request
    rv = self.dispatch_request()
  File "D:\My-Projects\U\projects\TodoApp\venv\lib\site-packages\flask\app.py", line 1509, in dispatch_request
    return self.ensure_sync(self.view_functions[rule.endpoint])(**req.view_args)
  File "D:\My-Projects\U\projects\Fyyur\main.py", line 242, in create_venue_submission
    flash('Venue ' + request.form['name'] + ' was successfully listed!')
  File "D:\My-Projects\U\projects\TodoApp\venv\lib\site-packages\flask\helpers.py", line 389, in flash
    session["_flashes"] = flashes
  File "D:\My-Projects\U\projects\TodoApp\venv\lib\site-packages\flask\sessions.py", line 97, in _fail
    raise RuntimeError(
RuntimeError: The session is unavailable because no secret key was set.  Set the secret_key on the application to something unique and secret.
2022-05-26 10:33:50,707 INFO: errors [in D:\My-Projects\U\projects\Fyyur\main.py:524]
2022-05-26 10:33:56,108 ERROR: Exception on /venues/2 [GET] [in D:\My-Projects\U\projects\TodoApp\venv\lib\site-packages\flask\app.py:1455]
Traceback (most recent call last):
  File "D:\My-Projects\U\projects\TodoApp\venv\lib\site-packages\flask\app.py", line 2077, in wsgi_app
    response = self.full_dispatch_request()
  File "D:\My-Projects\U\projects\TodoApp\venv\lib\site-packages\flask\app.py", line 1525, in full_dispatch_request
    rv = self.handle_user_exception(e)
  File "D:\My-Projects\U\projects\TodoApp\venv\lib\site-packages\flask\app.py", line 1523, in full_dispatch_request
    rv = self.dispatch_request()
  File "D:\My-Projects\U\projects\TodoApp\venv\lib\site-packages\flask\app.py", line 1509, in dispatch_request
    return self.ensure_sync(self.view_functions[rule.endpoint])(**req.view_args)
  File "D:\My-Projects\U\projects\Fyyur\main.py", line 135, in show_venue
    my_venue = Venue.get(venue_id);
AttributeError: type object 'Venue' has no attribute 'get'
2022-05-26 10:34:33,170 INFO: errors [in D:\My-Projects\U\projects\Fyyur\main.py:525]
2022-05-26 10:34:47,341 ERROR: Exception on /venues/2 [GET] [in D:\My-Projects\U\projects\TodoApp\venv\lib\site-packages\flask\app.py:1455]
Traceback (most recent call last):
  File "D:\My-Projects\U\projects\TodoApp\venv\lib\site-packages\flask\app.py", line 2077, in wsgi_app
    response = self.full_dispatch_request()
  File "D:\My-Projects\U\projects\TodoApp\venv\lib\site-packages\flask\app.py", line 1525, in full_dispatch_request
    rv = self.handle_user_exception(e)
  File "D:\My-Projects\U\projects\TodoApp\venv\lib\site-packages\flask\app.py", line 1523, in full_dispatch_request
    rv = self.dispatch_request()
  File "D:\My-Projects\U\projects\TodoApp\venv\lib\site-packages\flask\app.py", line 1509, in dispatch_request
    return self.ensure_sync(self.view_functions[rule.endpoint])(**req.view_args)
  File "D:\My-Projects\U\projects\Fyyur\main.py", line 135, in show_venue
    my_venue = Venue.get(venue_id)
AttributeError: type object 'Venue' has no attribute 'get'
2022-05-26 10:35:56,469 INFO: errors [in D:\My-Projects\U\projects\Fyyur\main.py:525]
2022-05-26 10:36:05,903 ERROR: Exception on /venues/1 [GET] [in D:\My-Projects\U\projects\TodoApp\venv\lib\site-packages\flask\app.py:1455]
Traceback (most recent call last):
  File "D:\My-Projects\U\projects\TodoApp\venv\lib\site-packages\flask\app.py", line 2077, in wsgi_app
    response = self.full_dispatch_request()
  File "D:\My-Projects\U\projects\TodoApp\venv\lib\site-packages\flask\app.py", line 1525, in full_dispatch_request
    rv = self.handle_user_exception(e)
  File "D:\My-Projects\U\projects\TodoApp\venv\lib\site-packages\flask\app.py", line 1523, in full_dispatch_request
    rv = self.dispatch_request()
  File "D:\My-Projects\U\projects\TodoApp\venv\lib\site-packages\flask\app.py", line 1509, in dispatch_request
    return self.ensure_sync(self.view_functions[rule.endpoint])(**req.view_args)
  File "D:\My-Projects\U\projects\Fyyur\main.py", line 135, in show_venue
    my_venue = Venue.get(1)
AttributeError: type object 'Venue' has no attribute 'get'
2022-05-26 10:36:43,094 INFO: errors [in D:\My-Projects\U\projects\Fyyur\main.py:526]
2022-05-26 10:36:47,679 ERROR: Exception on /venues/1 [GET] [in D:\My-Projects\U\projects\TodoApp\venv\lib\site-packages\flask\app.py:1455]
Traceback (most recent call last):
  File "D:\My-Projects\U\projects\TodoApp\venv\lib\site-packages\flask\app.py", line 2077, in wsgi_app
    response = self.full_dispatch_request()
  File "D:\My-Projects\U\projects\TodoApp\venv\lib\site-packages\flask\app.py", line 1525, in full_dispatch_request
    rv = self.handle_user_exception(e)
  File "D:\My-Projects\U\projects\TodoApp\venv\lib\site-packages\flask\app.py", line 1523, in full_dispatch_request
    rv = self.dispatch_request()
  File "D:\My-Projects\U\projects\TodoApp\venv\lib\site-packages\flask\app.py", line 1509, in dispatch_request
    return self.ensure_sync(self.view_functions[rule.endpoint])(**req.view_args)
  File "D:\My-Projects\U\projects\Fyyur\main.py", line 136, in show_venue
    my_venue = Venue.get(1)
AttributeError: type object 'Venue' has no attribute 'get'
2022-05-26 10:37:37,117 INFO: errors [in D:\My-Projects\U\projects\Fyyur\main.py:523]
